Workbook

Sheet 工作表1
F13: 多空
F14: 多
F33: 空

Sheet 總表
A2: 帳戶淨值 | B2: =按股票分類!D19 -> 25326391 | E2: =按股票分類!D11/按股票分類!D19 -> 1.5171306 | F2: 持股水位
A3: 日期 | B3: =MAX(A:A) -> 46275
A4: 12/31金額 | B4: 36228004
A6: 交易日期 | B6: 總淨值 | C6: 淨值 | D6: 股數 | E6: 單日損益 | F6: 自己淨值861 | G6: 淨值 | H6: 股數 | I6: 家人淨值1981 | J6: 淨值 | K6: 持股金額 | L6: 加權報酬指數 | M6: 櫃買報酬指數 | N6: 損益%YTD | O6: 損益%YTD(自己) | P6: 損益%YTD(家人) | Q6: 加權報酬% | R6: 櫃買指數 | S6: DD | T6: 淨多單% | U6: 指數期貨
A7: 46023 | B7: 12380372 | C7: 10 | D7: 1238037 | E7: 0 | F7: 8610442.1 | G7: =F7/H7 -> 10 | H7: 861044.21 | I7: =B7-F7 -> 3769929.9 | J7: =I7/#REF! -> #REF! | K7: 13733308 | L7: 65905.98 | M7: 504.71 | N7: 0 | O7: 0 | P7: 0 | Q7: 0 | R7: 0 | S7: =C7/MAX($C$7:C7)-1 -> 0 | T7: =K7/B7 -> 1.1092807 | U7: 0
A8: 46024 | B8: 12484309 | C8: 10.083955 | D8: 1238037 | E8: 103937 | F8: 16182750 | G8: #REF! | H8: #REF! | I8: 5551891.5 | J8: 3.3870332 | K8: 13837245 | L8: 66784.78 | M8: 507.97 | N8: =C8/C$7-1 -> 0.008395468 | O8: =G8/G$7-1 -> #REF! | P8: =J8/J$7-1 -> #REF! | Q8: =L8/L$7-1 -> 0.013334147 | R8: =M8/M$7-1 -> 0.0064591548 | S8: 0 | T8: 1.1083709 | U8: 0
A9: 46027 | B9: 12483816 | C9: 10.083556 | D9: 1238037 | E9: -493 | F9: 16182750 | G9: #REF! | H9: #REF! | I9: 5551891.5 | J9: 3.3870332 | K9: 12545898 | L9: 68503.29 | M9: 503.65 | N9: =C9/C$7-1 -> 0.0083556469 | O9: =G9/G$7-1 -> #REF! | P9: =J9/J$7-1 -> #REF! | Q9: =L9/L$7-1 -> 0.039409322 | R9: =M9/M$7-1 -> -0.002100216 | S9: -3.948957e-05 | T9: 1.004973 | U9: 0
A10: 46028 | B10: 12849074 | C10: 10.378586 | D10: 1238037 | E10: 365258 | F10: 16182750 | G10: #REF! | H10: #REF! | I10: 5551891.5 | J10: 3.3870332 | K10: 9940550 | L10: 69608.78 | M10: 509.7 | N10: =C10/C$7-1 -> 0.037858642 | O10: =G10/G$7-1 -> #REF! | P10: =J10/J$7-1 -> #REF! | Q10: =L10/L$7-1 -> 0.056183066 | R10: =M10/M$7-1 -> 0.0098868657 | S10: 0 | T10: 0.77363941 | U10: 0
A11: 46029 | B11: 12885539 | C11: 10.40804 | D11: 1238037 | E11: 36465 | F11: 16182750 | G11: #REF! | H11: #REF! | I11: 5551891.5 | J11: 3.3870332 | K11: 10433100 | L11: 69288.18 | M11: 514.22 | N11: =C11/C$7-1 -> 0.040804031 | O11: =G11/G$7-1 -> #REF! | P11: =J11/J$7-1 -> #REF! | Q11: =L11/L$7-1 -> 0.05131856 | R11: =M11/M$7-1 -> 0.018842504 | S11: 0 | T11: 0.80967509 | U11: 0
A12: 46030 | B12: 12816377 | C12: 10.352176 | D12: 1238037 | E12: -69162 | F12: 16182750 | G12: #REF! | H12: #REF! | I12: 5551891.5 | J12: 3.3870332 | K12: 10889472 | L12: 69114.96 | M12: 511.70032 | N12: =C12/C$7-1 -> 0.035217607 | O12: =G12/G$7-1 -> #REF! | P12: =J12/J$7-1 -> #REF! | Q12: =L12/L$7-1 -> 0.048690264 | R12: =M12/M$7-1 -> 0.013850175 | S12: -0.0053674123 | T12: 0.84965291 | U12: 0
A13: 46031 | B13: 12677733 | C13: 10.240189 | D13: 1238037 | E13: -138644 | F13: 16182750 | G13: #REF! | H13: #REF! | I13: 5551891.5 | J13: 3.3870332 | K13: 10613300 | L13: 68955.23 | M13: 511.35 | N13: =C13/C$7-1 -> 0.024018911 | O13: =G13/G$7-1 -> #REF! | P13: =J13/J$7-1 -> #REF! | Q13: =L13/L$7-1 -> 0.046266667 | R13: =M13/M$7-1 -> 0.01315607 | S13: -0.016127071 | T13: 0.83716071 | U13: 0
A14: 46034 | B14: 12859856 | C14: 10.387295 | D14: 1238037 | E14: 182123 | F14: 16182750 | G14: #REF! | H14: #REF! | I14: 5551891.5 | J14: 3.3870332 | K14: 11582400 | L14: 69588.87 | M14: 523.66 | N14: =C14/C$7-1 -> 0.038729537 | O14: =G14/G$7-1 -> #REF! | P14: =J14/J$7-1 -> #REF! | Q14: =L14/L$7-1 -> 0.055880969 | R14: =M14/M$7-1 -> 0.037546314 | S14: -0.0019931646 | T14: 0.90066327 | U14: 0
A15: 46035 | B15: 13181545 | C15: 10.647133 | D15: 1238037 | E15: 321689 | F15: 16182750 | G15: #REF! | H15: #REF! | I15: 5551891.5 | J15: 3.3870332 | K15: 16090150 | L15: 69907.42 | M15: 521.44 | N15: =C15/C$7-1 -> 0.064713332 | O15: =G15/G$7-1 -> #REF! | P15: =J15/J$7-1 -> #REF! | Q15: =L15/L$7-1 -> 0.060714369 | R15: =M15/M$7-1 -> 0.033147748 | S15: 0 | T15: 1.2206574 | U15: 0
A16: 46036 | B16: 13464210 | C16: 10.87545 | D16: 1238037 | E16: 282665 | F16: 16182750 | G16: #REF! | H16: #REF! | I16: 5551891.5 | J16: 3.3870332 | K16: 18199125 | L16: 70441.42 | M16: 531.02 | N16: =C16/C$7-1 -> 0.087545041 | O16: =G16/G$7-1 -> #REF! | P16: =J16/J$7-1 -> #REF! | Q16: =L16/L$7-1 -> 0.068816821 | R16: =M16/M$7-1 -> 0.052128945 | S16: 0 | T16: 1.3516668 | U16: 0
A17: 46037 | B17: 13676785 | C17: 11.047154 | D17: 1238037 | E17: 212575 | F17: 16182750 | G17: #REF! | H17: #REF! | I17: 5551891.5 | J17: 3.3870332 | K17: 18411700 | L17: 70142.74 | M17: 532.09 | N17: =C17/C$7-1 -> 0.10471537 | O17: =G17/G$7-1 -> #REF! | P17: =J17/J$7-1 -> #REF! | Q17: =L17/L$7-1 -> 0.06428491 | R17: =M17/M$7-1 -> 0.054248975 | S17: 0 | T17: 1.3462009 | U17: 0
A18: 46038 | B18: 13245485 | C18: 10.69878 | D18: 1238037 | E18: -431300 | F18: 16182750 | G18: #REF! | H18: #REF! | I18: 5551891.5 | J18: 3.3870332 | K18: 17980400 | L18: 71504.42 | M18: 535.05 | N18: =C18/C$7-1 -> 0.06987796 | O18: =G18/G$7-1 -> #REF! | P18: =J18/J$7-1 -> #REF! | Q18: =L18/L$7-1 -> 0.084945858 | R18: =M18/M$7-1 -> 0.060113729 | S18: -0.031535189 | T18: 1.3574739 | U18: 0
A19: 46041 | B19: 13700907 | C19: 11.066638 | D19: 1238037 | E19: 455422 | F19: 16182750 | G19: #REF! | H19: #REF! | I19: 5551891.5 | J19: 3.3870332 | K19: 19423170 | L19: 72029.36 | M19: 539.31 | N19: =C19/C$7-1 -> 0.10666377 | O19: =G19/G$7-1 -> #REF! | P19: =J19/J$7-1 -> #REF! | Q19: =L19/L$7-1 -> 0.092910841 | R19: =M19/M$7-1 -> 0.068554219 | S19: 0 | T19: 1.4176558 | U19: 0
... A35: 46063 | B35: 13390586 | C35: 10.815982 | D35: 1238037 | E35: -311776 | F35: 16182750 | G35: #REF! | H35: #REF! | I35: 5551891.5 | J35: 3.3870332 | K35: 8453050 | L35: 75293.33 | M35: 541.89 | N35: =C35/C$7-1 -> 0.081598207 | O35: =G35/G$7-1 -> #REF! | P35: =J35/J$7-1 -> #REF! | Q35: =L35/L$7-1 -> 0.14243548 | R35: =M35/M$7-1 -> 0.073666066 | S35: -0.0991138 | T35: 0.63126812 | U35: 0
A36: 46064 | B36: 13662834 | C36: =B36/D36 -> 11.035885 | D36: 1238037 | E36: =B36-B35 -> 272248 | F36: 16182750 | G36: #REF! | H36: #REF! | I36: 5551891.5 | J36: 3.3870332 | K36: 17892033 | L36: 76506.14 | M36: 544.07 | N36: =C36/C$7-1 -> 0.1035885 | O36: =G36/G$7-1 -> #REF! | P36: =J36/J$7-1 -> #REF! | Q36: =L36/L$7-1 -> 0.16083761 | R36: =M36/M$7-1 -> 0.077985378 | S36: -0.081833688 | T36: 1.3110181 | U36: 0
A37: 46076 | B37: 13919690 | C37: 11.243355 | D37: 1238037 | E37: 256856 | F37: 16182750 | G37: #REF! | H37: #REF! | I37: 5551891.5 | J37: 3.3870332 | K37: 20332385 | L37: 76887.59 | M37: 555.28 | N37: =C37/C$7-1 -> 0.12433554 | O37: =G37/G$7-1 -> #REF! | P37: =J37/J$7-1 -> #REF! | Q37: =L37/L$7-1 -> 0.1666254 | R37: =M37/M$7-1 -> 0.10019615 | S37: -0.063516964 | T37: 1.4606924 | U37: 0
A38: 46077 | B38: 15176285 | C38: 12.258345 | D38: 1238037 | E38: 1256595 | F38: 16182750 | G38: #REF! | H38: #REF! | I38: 5551891.5 | J38: 3.3870332 | K38: 21588980 | L38: 78999.25 | M38: 569.17 | N38: =C38/C$7-1 -> 0.22583453 | O38: =G38/G$7-1 -> #REF! | P38: =J38/J$7-1 -> #REF! | Q38: =L38/L$7-1 -> 0.19866589 | R38: =M38/M$7-1 -> 0.12771691 | S38: 0 | T38: 1.4225471 | U38: 0
A39: 46078 | B39: 15679512 | C39: 12.664817 | D39: 1238037 | E39: 503227 | F39: 16182750 | G39: #REF! | H39: #REF! | I39: 5551891.5 | J39: 3.3870332 | K39: 22977405 | L39: 80620.75 | M39: 572.46 | N39: =C39/C$7-1 -> 0.2664817 | O39: =G39/G$7-1 -> #REF! | P39: =J39/J$7-1 -> #REF! | Q39: =L39/L$7-1 -> 0.22326912 | R39: =M39/M$7-1 -> 0.1342355 | S39: 0 | T39: 1.4654413 | U39: 0
A40: 46079 | B40: 15793540 | C40: 12.756921 | D40: 1238037 | E40: 114028 | F40: 16182750 | G40: #REF! | H40: #REF! | I40: 5551891.5 | J40: 3.3870332 | K40: 25677050 | L40: 80623.98 | M40: 578.84 | N40: =C40/C$7-1 -> 0.27569208 | O40: =G40/G$7-1 -> #REF! | P40: =J40/J$7-1 -> #REF! | Q40: =L40/L$7-1 -> 0.22331813 | R40: =M40/M$7-1 -> 0.14687642 | S40: 0 | T40: 1.6257945 | U40: 0
A41: 46083 | B41: 15833840 | C41: 12.789472 | D41: 1238037 | E41: 40300 | F41: 16182750 | G41: #REF! | H41: #REF! | I41: 5551891.5 | J41: 3.3870332 | K41: 25717350 | L41: 79898.364 | M41: 577.50867 | N41: =C41/C$7-1 -> 0.27894724 | O41: =G41/G$7-1 -> #REF! | P41: =J41/J$7-1 -> #REF! | Q41: =L41/L$7-1 -> 0.21230826 | R41: =M41/M$7-1 -> 0.14423861 | S41: 0 | T41: 1.6242017 | U41: 0
A42: 46084 | B42: 14707335 | C42: 11.87956 | D42: 1238037 | E42: -1126505 | F42: 16182750 | G42: #REF! | H42: #REF! | I42: 5551891.5 | J42: 3.3870332 | K42: 23299180 | L42: 78140.6 | M42: 564.38 | N42: =C42/C$7-1 -> 0.18795601 | O42: =G42/G$7-1 -> #REF! | P42: =J42/J$7-1 -> #REF! | Q42: =L42/L$7-1 -> 0.18563748 | R42: =M42/M$7-1 -> 0.11822631 | S42: -0.071145408 | T42: 1.5841878 | U42: 0
A43: 46085 | B43: 12983661 | C43: 10.487296 | D43: 1238037 | E43: -1723674 | F43: 16182750 | G43: #REF! | H43: #REF! | I43: 5551891.5 | J43: 3.3870332 | K43: 4594450 | L43: 74727.64 | M43: 536.95113 | N43: =C43/C$7-1 -> 0.048729642 | O43: =G43/G$7-1 -> #REF! | P43: =J43/J$7-1 -> #REF! | Q43: =L43/L$7-1 -> 0.13385219 | R43: =M43/M$7-1 -> 0.06388051 | S43: -0.18000555 | T43: 0.35386398 | U43: 0
A44: 46086 | B44: 13209080 | C44: 10.669374 | D44: 1238037 | E44: 225419 | F44: 16182750 | G44: #REF! | H44: #REF! | I44: 5551891.5 | J44: 3.3870332 | K44: 8807400 | L44: 76659.21 | M44: 555.97 | N44: =C44/C$7-1 -> 0.066937418 | O44: =G44/G$7-1 -> #REF! | P44: =J44/J$7-1 -> #REF! | Q44: =L44/L$7-1 -> 0.16316016 | R44: =M44/M$7-1 -> 0.10156327 | S44: -0.16576901 | T44: 0.66676862 | U44: 0
A45: 46087 | B45: 13453109 | C45: 10.866484 | D45: 1238037 | E45: 244029 | F45: 16182750 | G45: #REF! | H45: #REF! | I45: 5551891.5 | J45: 3.3870332 | K45: 9890564 | L45: 76492.11 | M45: 560.13 | N45: =C45/C$7-1 -> 0.08664838 | O45: =G45/G$7-1 -> #REF! | P45: =J45/J$7-1 -> #REF! | Q45: =L45/L$7-1 -> 0.16062473 | R45: =M45/M$7-1 -> 0.10980563 | S45: -0.15035715 | T45: 0.73518798 | U45: 0
A46: 46090 | B46: 12676583 | C46: 10.23926 | D46: 1238037 | E46: -776526 | F46: 16182750 | G46: #REF! | H46: #REF! | I46: 5551891.5 | J46: 3.3870332 | K46: 9114038 | L46: 73103.51 | M46: 528.09056 | N46: =C46/C$7-1 -> 0.023926022 | O46: =G46/G$7-1 -> #REF! | P46: =J46/J$7-1 -> #REF! | Q46: =L46/L$7-1 -> 0.10920905 | R46: =M46/M$7-1 -> 0.046324749 | S46: -0.19939932 | T46: 0.71896646 | U46: 0
A47: 46091 | B47: 12977430 | C47: 10.482263 | D47: 1238037 | E47: 300847 | F47: 16182750 | G47: #REF! | H47: #REF! | I47: 5551891.5 | J47: 3.3870332 | K47: 9473355 | L47: 74607.85 | M47: 543.75 | N47: =C47/C$7-1 -> 0.048226345 | O47: =G47/G$7-1 -> #REF! | P47: =J47/J$7-1 -> #REF! | Q47: =L47/L$7-1 -> 0.1320346 | R47: =M47/M$7-1 -> 0.07735135 | S47: -0.18039907 | T47: 0.72998699 | U47: 0
A48: 46092 | B48: 13418097 | C48: 10.838204 | D48: 1238037 | E48: 440667 | F48: 16182750 | G48: #REF! | H48: #REF! | I48: 5551891.5 | J48: 3.3870332 | K48: 17363195 | L48: 77663.74 | M48: 569.3 | N48: =C48/C$7-1 -> 0.083820354 | O48: =G48/G$7-1 -> #REF! | P48: =J48/J$7-1 -> #REF! | Q48: =L48/L$7-1 -> 0.17840202 | R48: =M48/M$7-1 -> 0.12797448 | S48: -0.15256836 | T48: 1.2940132 | U48: 0
... A67: 46121 | B67: 16229888 | C67: 13.109372 | D67: 1238037 | E67: -212369 | F67: 16182750 | G67: #REF! | H67: #REF! | I67: 5551891.5 | J67: 3.3870332 | K67: 19877630 | L67: 79523.06 | M67: 627.51 | N67: =C67/C$7-1 -> 0.31093723 | O67: =G67/G$7-1 -> #REF! | P67: =J67/J$7-1 -> #REF! | Q67: =L67/L$7-1 -> 0.20661372 | R67: =M67/M$7-1 -> 0.24330804 | S67: -0.012916049 | T67: 1.2247546 | U67: 0
A68: 46122 | B68: 16527928 | C68: =B68/D68 -> 13.350108 | D68: 1238037 | E68: =B68-B67 -> 298040 | F68: 16182750 | G68: #REF! | H68: #REF! | I68: 5551891.5 | J68: 3.3870332 | K68: 23000645 | L68: 80793.42 | M68: 640.24 | N68: =C68/C$7-1 -> 0.33501083 | O68: =G68/G$7-1 -> #REF! | P68: =J68/J$7-1 -> #REF! | Q68: =L68/L$7-1 -> 0.22588906 | R68: =M68/M$7-1 -> 0.26853044 | S68: 0 | T68: 1.3919178 | U68: 0
A69: 46125 | B69: 16349000 | C69: 13.205583 | D69: 1238037 | E69: -178928 | F69: 16182750 | G69: #REF! | H69: #REF! | I69: 5551891.5 | J69: 3.3870332 | K69: 22709775 | L69: 80883.44 | M69: 645.25 | N69: =C69/C$7-1 -> 0.32055827 | O69: =G69/G$7-1 -> #REF! | P69: =J69/J$7-1 -> #REF! | Q69: =L69/L$7-1 -> 0.22725495 | R69: =M69/M$7-1 -> 0.27845694 | S69: -0.010825797 | T69: 1.389062 | U69: 0
A70: 46126 | B70: 16508085 | C70: 13.33408 | D70: 1238037 | E70: 159085 | F70: 16182750 | G70: #REF! | H70: #REF! | I70: 5551891.5 | J70: 3.3870332 | K70: 22868860 | L70: 82796.95 | M70: 652.15 | N70: =C70/C$7-1 -> 0.33340805 | O70: =G70/G$7-1 -> #REF! | P70: =J70/J$7-1 -> #REF! | Q70: =L70/L$7-1 -> 0.25628888 | R70: =M70/M$7-1 -> 0.29212815 | S70: -0.001200574 | T70: 1.3853127 | U70: 0
A71: 46127 | B71: 17234543 | C71: 13.920863 | D71: 1238037 | E71: 726458 | F71: 16182750 | G71: #REF! | H71: #REF! | I71: 5551891.5 | J71: 3.3870332 | K71: 19428475 | L71: 83768.84 | M71: 659.22 | N71: =C71/C$7-1 -> 0.39208626 | O71: =G71/G$7-1 -> #REF! | P71: =J71/J$7-1 -> #REF! | Q71: =L71/L$7-1 -> 0.2710355 | R71: =M71/M$7-1 -> 0.3061362 | S71: 0 | T71: 1.1272985 | U71: 0
A72: 46128 | B72: 17338395 | C72: 14.004747 | D72: 1238037 | E72: 103852 | F72: 16182750 | G72: #REF! | H72: #REF! | I72: 5551891.5 | J72: 3.3870332 | K72: 29462760 | L72: 84707.06 | M72: 670.79 | N72: =C72/C$7-1 -> 0.4004747 | O72: =G72/G$7-1 -> #REF! | P72: =J72/J$7-1 -> #REF! | Q72: =L72/L$7-1 -> 0.28527123 | R72: =M72/M$7-1 -> 0.32906025 | S72: 0 | T72: 1.6992784 | U72: 0
A73: 46129 | B73: 18230252 | C73: 14.725127 | D73: 1238037 | E73: 891857 | F73: 16182750 | G73: #REF! | H73: #REF! | I73: 5551891.5 | J73: 3.3870332 | K73: 33751036 | L73: 83959.54 | M73: 682.49 | N73: =C73/C$7-1 -> 0.4725127 | O73: =G73/G$7-1 -> #REF! | P73: =J73/J$7-1 -> #REF! | Q73: =L73/L$7-1 -> 0.27392901 | R73: =M73/M$7-1 -> 0.35224188 | S73: 0 | T73: 1.8513752 | U73: 0
A74: 46132 | B74: 18768601 | C74: 15.159968 | D74: 1238037 | E74: 538349 | F74: 16182750 | G74: #REF! | H74: #REF! | I74: 5551891.5 | J74: 3.3870332 | K74: 33554046 | L74: 84311.91 | M74: 702.94 | N74: =C74/C$7-1 -> 0.51599678 | O74: =G74/G$7-1 -> #REF! | P74: =J74/J$7-1 -> #REF! | Q74: =L74/L$7-1 -> 0.27927557 | R74: =M74/M$7-1 -> 0.3927602 | S74: 0 | T74: 1.7877756 | U74: 0
A75: 46133 | B75: 19762419 | C75: 15.962705 | D75: 1238037 | E75: 993818 | F75: 16182750 | G75: #REF! | H75: #REF! | I75: 5551891.5 | J75: 3.3870332 | K75: 35771530 | L75: 85786.3 | M75: 715.8741 | N75: =C75/C$7-1 -> 0.59627047 | O75: =G75/G$7-1 -> #REF! | P75: =J75/J$7-1 -> #REF! | Q75: =L75/L$7-1 -> 0.30164668 | R75: =M75/M$7-1 -> 0.41838699 | S75: 0 | T75: 1.8100785 | U75: 0
...

Sheet 按股票分類
C2: 股票 | D2: 今日市值 | E2: 百分比 | F2: 今日融資金額 | G2: 昨日市值 | H2: 變化值 | I2: 昨日融資金額 | J2: 變化百分比 | K2: 類股 | L2: 月線(20MA) | M2: 股價 | N2: 月線乖離率 | O2: 價格上下波動10%對損益的影響
C3: 仁新(6696) | D3: =帳戶!F4 -> 9229250 | E3: =D3/$D$19 -> 0.36441236 | F3: =帳戶!E4 -> 0 | G3: 8136000 | H3: =D3-G3 -> 1093250 | I3: 0 | J3: =IFERROR(H3/G3,"n/a") -> 0.13437193 | K3: 生技醫療業 | O3: =D3*0.1 -> 922925
C4: 凱基金(2883) | D4: =帳戶!F5 -> 8407200 | E4: =D4/$D$19 -> 0.33195413 | F4: =帳戶!E5 -> 4475000 | G4: 8316800 | H4: =D4-G4 -> 90400 | I4: 4475000 | J4: =IFERROR(H4/G4,"n/a") -> 0.010869565 | K4: 金融 | O4: =D4*0.1 -> 840720
C5: 聯發科(2454) | D5: =帳戶!F6 -> 5697040 | E5: =D5/$D$19 -> 0.2249448 | F5: =帳戶!E6 -> 2907000 | G5: 4796680 | H5: =D5-G5 -> 900360 | I5: 2907000 | J5: =IFERROR(H5/G5,"n/a") -> 0.18770483 | K5: 半導體 | O5: =D5*0.1 -> 569704
C6: 台新新光金(2887) | D6: =帳戶!F11 -> 5479500 | E6: =D6/$D$19 -> 0.21635534 | F6: =帳戶!E11 -> 2897000 | G6: 5512000 | H6: =D6-G6 -> -32500 | I6: 2897000 | J6: =IFERROR(H6/G6,"n/a") -> -0.0058962264 | K6: 金融 | O6: =D6*0.1 -> 547950
C7: 富邦金(2881) | D7: =帳戶!F7 -> 4917000 | E7: =D7/$D$19 -> 0.19414531 | F7: =帳戶!E7 -> 2819000 | G7: 4867500 | H7: =D7-G7 -> 49500 | I7: 2819000 | J7: =IFERROR(H7/G7,"n/a") -> 0.010169492 | K7: 金融 | O7: =D7*0.1 -> 491700
C8: 緯穎(6669) | D8: =帳戶!F9 -> 2928100 | E8: =D8/$D$19 -> 0.11561458 | F8: =帳戶!E9 -> 0 | G8: 2903180 | H8: =D8-G8 -> 24920 | I8: 0 | J8: =IFERROR(H8/G8,"n/a") -> 0.008583691 | K8: 金融 | O8: =D8*0.1 -> 292810
C9: 中華立鼎(7926) | D9: =帳戶!F8 -> 1765352 | E9: =D9/$D$19 -> 0.069704049 | F9: 0 | G9: 2662200 | H9: =D9-G9 -> -896848 | I9: 0 | J9: =IFERROR(H9/G9,"n/a") -> -0.33688228 | K9: CPO | O9: =D9*0.1 -> 176535.2
C10: 仲恩生醫(7729) | D10: =帳戶!F10 -> 0 | E10: =D10/$D$19 -> 0 | F10: 0 | G10: 1155000 | H10: =D10-G10 -> -1155000 | I10: 0 | J10: =IFERROR(H10/G10,"n/a") -> -1 | K10: 生技醫療業 | O10: =D10*0.1 -> 0
C11: Total | D11: =SUM(D3:D10) -> 38423442 | E11: =D11/$D$19 -> 1.5171306 | F11: =SUM(F3:F10) -> 13098000 | G11: =SUM(G3:G10) -> 38349360 | H11: =SUM(H3:H10) -> 74082 | I11: =SUM(I3:I10) -> 13098000 | J11: =IFERROR(H11/G11,"n/a") -> 0.0019317663 | O11: =SUM(O3:O10) -> 3842344.2
D12: 0 | E12: =D12/$D$19 -> 0 | F12: 0 | G12: 0 | H12: =D12-G12 -> 0 | I12: 0 | J12: =IFERROR(H12/G12,"n/a") -> n/a | O12: =D12*0.1 -> 0
C13: Total | D13: =SUM(D12:D12) -> 0 | G13: =SUM(G12:G12) -> 0 | H13: =D13-G13 -> 0 | J13: =IFERROR(H13/G13,"n/a") -> n/a | O13: =SUM(0) -> 0
C14: check | D14: =D14-帳戶!F14 -> 0 | G14: 0
C15: 現金 | D15: =帳戶!C20 -> 949 | E15: =D15/$D$19 -> 3.7470795e-05 | G15: 19731 | H15: =D15-G15 -> -18782 | J15: =H15/G15 -> -0.9519031 | K15: 現金
C16: 期貨(元大) | D16: =期貨!C4 -> 0 | E16: =D16/$D$19 -> 0 | G16: 0 | H16: =D16-G16 -> 0 | J16: =H16/G16 -> #DIV/0!
C17: 股利 | D17: =帳戶!C21 -> 0 | E17: =D17/$D$19 -> 0 | G17: 0 | H17: =D17-G17 -> 0 | J17: =H17/G17 -> #DIV/0! | K17: 未發放股利
C18: check | D18: =D11+D15-F11-帳戶!F23+D17 -> 0 | G18: 0
C19: Total | D19: =D11+D15-F11+D17+D16 -> 25326391 | E19: =D19/$D$19 -> 1 | G19: =G11+G15-I11+G17+G16 -> 25271091 | H19: =D19-G19 -> 55300 | J19: =H19/G19 -> 0.0021882712
C20: 昨日金額 | D20: 25271091
C21: 變化總量 | D21: =D19-D20 -> 55300
C22: 變化% | D22: =D21/D20 -> 0.0021882712

Sheet 帳戶
B2: 股票
B3: 標的 | C3: 股數 | D3: 收盤價 | E3: 融資金額 | F3: 市值
B4: 仁新 | C4: 55100 | D4: =VLOOKUP(B4,'[1]元大(自己)'!$B$4:$D$12,3,0) -> 167.5 | E4: 0 | F4: =C4*D4 -> 9229250
B5: 凱基金 | C5: 226000 | D5: =VLOOKUP(B5,'[1]元大(自己)'!$B$4:$D$12,3,0) -> 37.2 | E5: =2413000+745000+1317000 -> 4475000 | F5: =C5*D5 -> 8407200
B6: 聯發科 | C6: 1207 | D6: =VLOOKUP(B6,'[1]元大(自己)'!$B$4:$D$12,3,0) -> 4720 | E6: 2907000 | F6: =C6*D6 -> 5697040
B7: 富邦金 | C7: 33000 | D7: =VLOOKUP(B7,'[1]元大(自己)'!$B$4:$D$12,3,0) -> 149 | E7: 2819000 | F7: =C7*D7 -> 4917000
B8: 中華立鼎 | C8: 2962 | D8: =VLOOKUP(B8,'[1]元大(自己)'!$B$4:$D$12,3,0) -> 596 | E8: 0 | F8: =C8*D8 -> 1765352
B9: 緯穎 | C9: 1246 | D9: =VLOOKUP(B9,'[1]元大(自己)'!$B$4:$D$12,3,0) -> 2350 | E9: 0 | F9: =C9*D9 -> 2928100
B10: 仲恩生醫 | C10: 0 | D10: =VLOOKUP(B10,'[1]元大(自己)'!$B$4:$D$12,3,0) -> 126.5 | E10: 0 | F10: =C10*D10 -> 0
B11: 台新新光金 | C11: 130000 | D11: =VLOOKUP(B11,'[1]元大(自己)'!$B$4:$D$12,3,0) -> 42.15 | E11: =2408000+489000 -> 2897000 | F11: =C11*D11 -> 5479500
D14: 股票總計 | E14: =SUM(E4:E11) -> 13098000 | F14: =SUM(F4:F11) -> 38423442
B16: 現金
B17: 銀行餘額 | C17: 8338 | E17: 31.9
B18: T+1 | C18: 11393
B19: T+2 | C19: -18782
B20: 總計 | C20: =SUM(C17:C19) -> 949 | F20: =F23+期貨!C4 -> 25326391
B21: 股利 | C21: 0
D23: 權益總計 | F23: =F14+C20+C21-E14 -> 25326391
D27: =SUM(D28:D43) -> 0.99969 | H27: =(F23+期貨!C4)*0.67 -> 16968682 | K27: 開 | L27: 午 | M27: 收
B28: 8299 | C28: 群聯 | D28: 0.2127 | F28: 0.2127 | G28: 2670 | H28: =$H$27*F28/G28 -> 1351.7748 | I28: 1.3 | J28: =I28*G28 -> 3471 | K28: 1.3 | L28: 0 | M28: 0
B29: 2451 | C29: 創見 | D29: 0.08508 | F29: 0.08508 | G29: 343.5 | H29: =$H$27*F29/G29 -> 4202.898 | I29: 4 | J29: =I29*G29 -> 1374 | K29: 4 | L29: 0 | M29: 0
B30: 5289 | C30: 宜鼎 | D30: 0.08508 | F30: 0.08508 | G30: 1760 | H30: =$H$27*F30/G30 -> 820.28151 | I30: 1 | J30: =I30*G30 -> 1760 | K30: 1 | L30: 0 | M30: 0
B31: 3135 | C31: 凌航 | D31: 0.04254 | F31: 0.04254 | G31: 194.5 | H31: =$H$27*F31/G31 -> 3711.2994 | I31: 4 | J31: =I31*G31 -> 778 | K31: 4 | L31: 0 | M31: 0
B32: 8271 | C32: 宇瞻 | D32: 0.04254 | F32: 0.04254 | G32: 256 | H32: =$H$27*F32/G32 -> 2819.7177 | I32: 3 | J32: =I32*G32 -> 768 | K32: 3 | L32: 0 | M32: 0
B33: 3036 | C33: 文曄 | D33: 0.08508 | F33: 0.08508 | G33: 264.5 | H33: =$H$27*F33/G33 -> 5458.2059 | I33: 5 | J33: =I33*G33 -> 1322.5 | K33: 5 | L33: 0 | M33: 0
B34: 2059 | C34: 川湖 | D34: 0.08508 | F34: 0.08508 | G34: 5520 | H34: =$H$27*F34/G34 -> 261.53903 | I34: 0.3 | J34: =I34*G34 -> 1656 | K34: 0.3 | L34: 0 | M34: 0
B35: 3055 | C35: 蔚華科 | D35: 0.02127 | F35: 0.02127 | G35: 100 | H35: =$H$27*F35/G35 -> 3609.2387 | I35: 4 | J35: =I35*G35 -> 400 | K35: 4 | L35: 0 | M35: 0
B36: 3209 | C36: 全科 | D36: 0.02127 | F36: 0.02127 | G36: 60.5 | H36: =$H$27*F36/G36 -> 5965.6837 | I36: 6 | J36: =I36*G36 -> 363 | K36: 6 | L36: 0 | M36: 0
B37: 4973 | C37: 廣穎 | D37: 0.02127 | F37: 0.02127 | G37: 109.5 | H37: =$H$27*F37/G37 -> 3296.1084 | I37: 3 | J37: =I37*G37 -> 328.5 | K37: 3 | L37: 0 | M37: 0
B38: 6166 | C38: 凌華 | D38: 0.04254 | F38: 0.04254 | G38: 92.7 | H38: =$H$27*F38/G38 -> 7786.9227 | I38: 7 | J38: =I38*G38 -> 648.9 | K38: 7 | L38: 0 | M38: 0
B39: 6206 | C39: 飛捷 | D39: 0.04254 | F39: 0.04254 | G39: 130.5 | H39: =$H$27*F39/G39 -> 5531.4002 | I39: 5 | J39: =I39*G39 -> 652.5 | K39: 5 | L39: 0 | M39: 0
... B43: 6531 | C43: 愛普 | D43: 0.04254 | F43: 0.04254 | G43: 962 | H43: =$H$27*F43/G43 -> 750.36147 | I43: 1 | J43: =I43*G43 -> 962 | K43: 1 | L43: 0 | M43: 0
I46: =586.7-295 -> 291.7

Sheet 期貨
B3: 權益數
B4: 保證金 | C4: 0
B5: 權利金 | C5: 0
B6: 總計 | C6: =SUM(C4:C5) -> 0
